<?xml version='1.0'?>
<sdf version="1.4">
  <model name="raspi_robot_rover">
    <pose>0 0 0.5 0 0 0</pose>
    <static>false</static>
    <!-- Chassis with caster -->
    <link name='chassis'>
      <pose>0 0 .1 0 0 0</pose>
      <collision name='collision'>
        <geometry>
          <box>
            <size>.2 .13 .005</size>
          </box>
        </geometry>
      </collision>
      <visual name='visual'>
        <geometry>
          <box>
            <size>.2 .13 .005</size>
          </box>
        </geometry>
      </visual>
      <!-- Battery box -->
      <collision name='battery_box_collision'>
        <pose>-0.035 0 -0.007 0 0 0</pose>
        <geometry>
          <box>
            <size>.055 .09 .013</size>
          </box>
        </geometry>
      </collision>
      <visual name='battery_box_visual'>
        <geometry>
          <box>
            <size>.055 .09 .013</size>
          </box>
        </geometry>
        <material>
          <ambient>0.1 0.1 0.1 1</ambient>
          <diffuse>0.1 0.1 0.2 1</diffuse>
          <specular>0 0 0 0</specular>
          <emissive>0 0 0 1</emissive>
        </material>
      </visual>
      <!-- Caster -->
      <collision name='caster_collision'>
        <pose>-0.08 0 -0.025 0 0 0</pose>
        <geometry>
            <sphere>
            <radius>.02</radius>
          </sphere>
        </geometry>
        <surface>
          <friction>
            <ode>
              <mu>0</mu>
              <mu2>0</mu2>
              <slip1>1.0</slip1>
              <slip2>1.0</slip2>
            </ode>
          </friction>
        </surface>
      </collision>
      <visual name='caster_visual'>
        <pose>-0.08 0 -0.025 0 0 0</pose>
        <geometry>
          <sphere>
            <radius>.02</radius>
          </sphere>
        </geometry>
      </visual>
    </link>
    <!-- Left wheel -->
    <link name="left_wheel">
      <pose>0.03 -0.0825 0.1 0 1.5707 1.5707</pose>
      <collision name="collision">
        <geometry>
          <cylinder>
            <radius>.033</radius>
            <length>.025</length>
          </cylinder>
        </geometry>
      </collision>
      <visual name="visual">
        <geometry>
          <cylinder>
            <radius>.033</radius>
            <length>.025</length>
          </cylinder>
        </geometry>
      </visual>
    </link>
    <!-- Right wheel -->
    <link name="right_wheel">
      <pose>0.03 0.0825 0.1 0 1.5707 1.5707</pose>
      <collision name="collision">
        <geometry>
          <cylinder>
            <radius>.033</radius>
            <length>.025</length>
          </cylinder>
        </geometry>
      </collision>
      <visual name="visual">
        <geometry>
          <cylinder>
            <radius>.033</radius>
            <length>.025</length>
          </cylinder>
        </geometry>
      </visual>
    </link>
    <joint type="revolute" name="left_wheel_hinge">
      <pose>-0.012 0 -0.03 0 0 0</pose>
      <child>left_wheel</child>
      <parent>chassis</parent>
      <axis>
        <xyz>0 1 0</xyz>
      </axis>
    </joint>

    <joint type="revolute" name="right_wheel_hinge">
      <pose>-0.012 0 0.03 0 0 0</pose>
      <child>right_wheel</child>
      <parent>chassis</parent>
      <axis>
        <xyz>0 1 0</xyz>
      </axis>
    </joint>
  </model>
</sdf>
